Workbook

Sheet Project Guide
A1: WORLD TOP 100 COMPANIES BY MARKET CAPITALISATION
A3: Excel Project Title
A4: Using Excel analysis and an interactive dashboard, how can the world Top 100 companies ranked by market capitalisation be analysed to identify leading companies, sector and regional concentration, revenue and workforce patterns, and the distribution of company size?
A5: Scope | B5: World Top 100 companies by market capitalisation as captured on 31 August 2026. | E5: Market ranking source | F5: https://companiesmarketcap.com/
A6: Annual data | B6: Previously missing annual/profile fields were replaced using latest company annual reports or official investor-relations disclosures where available. | E6: Budget rule | F6: Not publicly disclosed
A7: Market cap | B7: Point-in-time market value on 31 August 2026. | E7: Revenue basis | F7: Source TTM where already available; latest completed FY used to replace previously missing revenue.
A8: Employees | B8: Latest annual/company-disclosed headcount where available. Explicit disclosure notes are used when a consolidated headcount is not separately stated. | E8: No generic placeholder | F8: Generic missing-value placeholders have been replaced with annual disclosure values or explicit disclosure notes.
A9: GitHub use | B9: PDF preview in the repository README and the Excel workbook as the downloadable analysis file. | E9: Reference date | F9: 31 August 2026
A12: Field | B12: Meaning | C12: Field | D12: Meaning | E12: Field | F12: Meaning
A13: Market Capitalisation (USD bn) | B13: Point-in-time equity value | C13: Revenue (USD bn) | D13: TTM or latest FY replacement | E13: Employees | F13: Latest annual headcount
A14: Sector | B14: Broad business grouping | C14: Region | D14: Geographic grouping | E14: Profit Margin (%) | F14: Retained where numeric from earlier market enrichment
A15: Year Founded | B15: Company formation year | C15: Stock Exchange | D15: Primary / major trading venue | E15: Market Source URL | F15: Ranking source
A16: Important limitation | B16: Market capitalisation changes daily. Annual employee and revenue fields update on company reporting cycles, so their dates do not perfectly match the market-cap snapshot.
A17: Source policy | B17: Market ranking: CompaniesMarketCap. Annual/profile data: latest official company annual report or investor-relations disclosure where available.
A18: Relationship analysis | B18: Market capitalisation is compared with TTM operating profit margin for the SAME companies in the market-cap Top 100. | E18: Method | F18: Pearson correlation + scatter plot + linear trendline
A19: Missing margins | B19: Companies without a current numeric operating margin from the market source are excluded, not assigned a value. | E19: Relationship sheet | F19: Relationship Analysis
A20: Interpretation | B20: Correlation describes association, not causation. The R-squared value indicates how much observed margin variation is linearly associated with market cap in the matched sample. | E20: Margin source | F20: CompaniesMarketCap company operating-margin pages
A21: Portfolio use | B21: The dashboard and GitHub PDF now include the size-versus-profitability relationship as a distinct analytical finding. | E21: Reference date | F21: 31 August 2026

Sheet Top 100 Market Cap
A1: WORLD TOP 100 COMPANIES BY MARKET CAPITALISATION
A2: Rank | B2: Company ID | C2: Company Name | D2: Ticker | E2: Country | F2: Region | G2: Sector | H2: Industry | I2: Stock Exchange | J2: Year Founded | K2: Employees | L2: Market Capitalisation (USD bn) | M2: Market Capitalisation (USD tn) | N2: Revenue (USD bn; TTM or latest FY) | O2: Operating Profit Margin (TTM, %) | P2: As-of Date | Q2: Market Source URL | R2: Annual Data Source | S2: Data Status | T2: Operating Margin Source URL
A3: 1 | B3: MC-001 | C3: NVIDIA | D3: NVDA | E3: USA | F3: North America | G3: Technology | H3: Semiconductors | I3: NASDAQ | J3: 1993 | K3: 42000 | L3: 5306 | M3: 5.306 | N3: 253.49 | O3: 0.7485 | P3: 46265 | Q3: https://companiesmarketcap.com/nvidia/ | R3: Official company annual report / investor-relations disclosure (latest completed annual disclosure retained from prior enrichment) | S3: 31 Aug 2026 market-cap snapshot + current TTM operating margin + latest annual/company disclosure | T3: https://companiesmarketcap.com/nvidia/operating-margin/
A4: 2 | B4: MC-002 | C4: Apple | D4: AAPL | E4: USA | F4: North America | G4: Technology | H4: Software | I4: NASDAQ | J4: 1976 | K4: 166000 | L4: 4609 | M4: 4.609 | N4: 451.44 | O4: 0.3189 | P4: 46265 | Q4: https://companiesmarketcap.com/apple/ | R4: Official company annual report / investor-relations disclosure (latest completed annual disclosure retained from prior enrichment) | S4: 31 Aug 2026 market-cap snapshot + current TTM operating margin + latest annual/company disclosure | T4: https://companiesmarketcap.com/apple/operating-margin/
A5: 3 | B5: MC-003 | C5: Alphabet (Google) | D5: GOOG | E5: USA | F5: North America | G5: Technology | H5: Software | I5: NASDAQ | J5: 1998 | K5: 190820 | L5: 4096 | M5: 4.096 | N5: 422.49 | O5: 0.4631 | P5: 46265 | Q5: https://companiesmarketcap.com/alphabet-google/ | R5: Official company annual report / investor-relations disclosure (latest completed annual disclosure retained from prior enrichment) | S5: 31 Aug 2026 market-cap snapshot + current TTM operating margin + latest annual/company disclosure | T5: https://companiesmarketcap.com/alphabet-google/operating-margin/
A6: 4 | B6: MC-004 | C6: Microsoft | D6: MSFT | E6: USA | F6: North America | G6: Technology | H6: Software | I6: NASDAQ | J6: 1975 | K6: 223000 | L6: 3783 | M6: 3.783 | N6: 318.27 | O6: 0.4854 | P6: 46265 | Q6: https://companiesmarketcap.com/microsoft/ | R6: Official company annual report / investor-relations disclosure (latest completed annual disclosure retained from prior enrichment) | S6: 31 Aug 2026 market-cap snapshot + current TTM operating margin + latest annual/company disclosure | T6: https://companiesmarketcap.com/microsoft/operating-margin/
A7: 5 | B7: MC-005 | C7: Amazon | D7: AMZN | E7: USA | F7: North America | G7: Technology | H7: E-Commerce | I7: NASDAQ | J7: 1994 | K7: 1576000 | L7: 2794 | M7: 2.794 | N7: 742.77 | O7: 0.1357 | P7: 46265 | Q7: https://companiesmarketcap.com/amazon/ | R7: Official company annual report / investor-relations disclosure (latest completed annual disclosure retained from prior enrichment) | S7: 31 Aug 2026 market-cap snapshot + current TTM operating margin + latest annual/company disclosure | T7: https://companiesmarketcap.com/amazon/operating-margin/
A8: 6 | B8: MC-006 | C8: TSMC | D8: TSM | E8: Taiwan | F8: Asia-Pacific | G8: Technology | H8: Semiconductors | I8: NYSE (ADR) / TWSE | J8: 1987 | K8: 90557 | L8: 2155 | M8: 2.155 | N8: 120.17 | O8: 0.536 | P8: 46265 | Q8: https://companiesmarketcap.com/tsmc/ | R8: Official company annual report / investor-relations disclosure (latest completed annual disclosure retained from prior enrichment) | S8: 31 Aug 2026 market-cap snapshot + current TTM operating margin + latest annual/company disclosure | T8: https://companiesmarketcap.com/tsmc/operating-margin/
A9: 7 | B9: MC-007 | C9: SpaceX | D9: SPCX | E9: USA | F9: North America | G9: Technology | H9: Tech | I9: Not available | J9: 2002 | K9: Not available | L9: 1876 | M9: 1.876 | N9: 8.76 | O9: -0.2259 | P9: 46265 | Q9: https://companiesmarketcap.com/spacex/ | R9: Official company annual report / investor-relations disclosure (latest completed annual disclosure retained from prior enrichment) | S9: 31 Aug 2026 market-cap snapshot + current TTM operating margin + latest annual/company disclosure | T9: https://companiesmarketcap.com/spacex/operating-margin/
A10: 8 | B10: MC-008 | C10: Broadcom | D10: AVGO | E10: USA | F10: North America | G10: Technology | H10: Semiconductors | I10: NASDAQ | J10: 1961 | K10: 33000 | L10: 1757 | M10: 1.757 | N10: 75.46 | O10: 0.4455 | P10: 46265 | Q10: https://companiesmarketcap.com/broadcom/ | R10: Official company annual report / investor-relations disclosure (latest completed annual disclosure retained from prior enrichment) | S10: 31 Aug 2026 market-cap snapshot + current TTM operating margin + latest annual/company disclosure | T10: https://companiesmarketcap.com/broadcom/operating-margin/
A11: 9 | B11: MC-009 | C11: Saudi Aramco | D11: 2222.SR | E11: S. Arabia | F11: Middle East & Africa | G11: Energy | H11: Oil&Gas | I11: Saudi Exchange | J11: 1933 | K11: 76664 | L11: 1679 | M11: 1.679 | N11: 459.04 | O11: 0.4247 | P11: 46265 | Q11: https://companiesmarketcap.com/saudi-aramco/ | R11: Official company annual report / investor-relations disclosure (latest completed annual disclosure retained from prior enrichment) | S11: 31 Aug 2026 market-cap snapshot + current TTM operating margin + latest annual/company disclosure | T11: https://companiesmarketcap.com/saudi-aramco/operating-margin/
A12: 10 | B12: MC-010 | C12: Meta Platforms (Facebook) | D12: META | E12: USA | F12: North America | G12: Technology | H12: Internet | I12: NASDAQ | J12: 2004 | K12: 78865 | L12: 1457 | M12: 1.457 | N12: 214.96 | O12: 0.4223 | P12: 46265 | Q12: https://companiesmarketcap.com/meta-platforms/ | R12: Official company annual report / investor-relations disclosure (latest completed annual disclosure retained from prior enrichment) | S12: 31 Aug 2026 market-cap snapshot + current TTM operating margin + latest annual/company disclosure | T12: https://companiesmarketcap.com/meta-platforms/operating-margin/
A13: 11 | B13: MC-011 | C13: Tesla | D13: TSLA | E13: USA | F13: North America | G13: Technology | H13: Automakers | I13: NASDAQ | J13: 2003 | K13: 134785 | L13: 1448 | M13: 1.448 | N13: 97.87 | O13: 0.059 | P13: 46265 | Q13: https://companiesmarketcap.com/tesla/ | R13: Official company annual report / investor-relations disclosure (latest completed annual disclosure retained from prior enrichment) | S13: 31 Aug 2026 market-cap snapshot + current TTM operating margin + latest annual/company disclosure | T13: https://companiesmarketcap.com/tesla/operating-margin/
A14: 12 | B14: MC-012 | C14: Samsung | D14: 005930.KS | E14: S. Korea | F14: Asia-Pacific | G14: Technology | H14: Semiconductors | I14: Korea Exchange | J14: 1969 | K14: 259149 | L14: 1248 | M14: 1.248 | N14: 270.94 | O14: 0.2553 | P14: 46265 | Q14: https://companiesmarketcap.com/samsung/ | R14: Official company annual report / investor-relations disclosure (latest completed annual disclosure retained from prior enrichment) | S14: 31 Aug 2026 market-cap snapshot + current TTM operating margin + latest annual/company disclosure | T14: https://companiesmarketcap.com/samsung/operating-margin/
A15: 13 | B15: MC-013 | C15: Berkshire Hathaway | D15: BRK-B | E15: USA | F15: North America | G15: Financials | H15: Investment | I15: NYSE | J15: 1839 | K15: 387800 | L15: 1078 | M15: 1.078 | N15: 385.68 | O15: 0.1601 | P15: 46265 | Q15: https://companiesmarketcap.com/berkshire-hathaway/ | R15: Official company annual report / investor-relations disclosure (latest completed annual disclosure retained from prior enrichment) | S15: 31 Aug 2026 market-cap snapshot + current TTM operating margin + latest annual/company disclosure | T15: https://companiesmarketcap.com/berkshire-hathaway/operating-margin/
A16: 14 | B16: MC-014 | C16: Micron Technology | D16: MU | E16: USA | F16: North America | G16: Technology | H16: Semiconductors | I16: NASDAQ | J16: 1978 | K16: 53000 | L16: 1066 | M16: 1.066 | N16: 90.27 | O16: 0.2582 | P16: 46265 | Q16: https://companiesmarketcap.com/micron-technology/ | R16: Official company annual report / investor-relations disclosure (latest completed annual disclosure retained from prior enrichment) | S16: 31 Aug 2026 market-cap snapshot + current TTM operating margin + latest annual/company disclosure | T16: https://companiesmarketcap.com/micron-technology/operating-margin/
A17: 15 | B17: MC-015 | C17: Eli Lilly | D17: LLY | E17: USA | F17: North America | G17: Technology | H17: Pharmaceuticals | I17: NYSE | J17: 1876 | K17: 33000 | L17: 1034 | M17: 1.034 | N17: 72.24 | O17: 0.4307 | P17: 46265 | Q17: https://companiesmarketcap.com/eli-lilly/ | R17: Official company annual report / investor-relations disclosure (latest completed annual disclosure retained from prior enrichment) | S17: 31 Aug 2026 market-cap snapshot + current TTM operating margin + latest annual/company disclosure | T17: https://companiesmarketcap.com/eli-lilly/operating-margin/
A18: 16 | B18: MC-016 | C18: JPMorgan Chase | D18: JPM | E18: USA | F18: North America | G18: Financials | H18: Banks | I18: NYSE | J18: 1799 | K18: 318512 | L18: 944.99 | M18: 0.94499 | N18: 186.94 | O18: 0.3994 | P18: 46265 | Q18: https://companiesmarketcap.com/jp-morgan-chase/ | R18: Official company annual report / investor-relations disclosure (latest completed annual disclosure retained from prior enrichment) | S18: 31 Aug 2026 market-cap snapshot + current TTM operating margin + latest annual/company disclosure | T18: https://companiesmarketcap.com/jp-morgan-chase/operating-margin/
A19: 17 | B19: MC-017 | C19: SK Hynix | D19: 000660.KS | E19: S. Korea | F19: Asia-Pacific | G19: Technology | H19: Semiconductors | I19: Korea Exchange | J19: 1983 | K19: Not separately stated in latest annual disclosure | L19: 868.67 | M19: 0.86867 | N19: 91.71 | O19: 0.7087 | P19: 46265 | Q19: https://companiesmarketcap.com/sk-hynix/ | R19: Official company annual report / investor-relations disclosure (latest completed annual disclosure retained from prior enrichment) | S19: 31 Aug 2026 market-cap snapshot + current TTM operating margin + latest annual/company disclosure | T19: https://companiesmarketcap.com/sk-hynix/operating-margin/
A20: 18 | B20: MC-018 | C20: Walmart | D20: WMT | E20: USA | F20: North America | G20: Consumer Discretionary | H20: Retail | I20: NASDAQ | J20: 1962 | K20: 2100000 | L20: 835.12 | M20: 0.83512 | N20: 725.3 | O20: 0.0413 | P20: 46265 | Q20: https://companiesmarketcap.com/walmart/ | R20: Official company annual report / investor-relations disclosure (latest completed annual disclosure retained from prior enrichment) | S20: 31 Aug 2026 market-cap snapshot + current TTM operating margin + latest annual/company disclosure | T20: https://companiesmarketcap.com/walmart/operating-margin/
A21: 19 | B21: MC-019 | C21: AMD | D21: AMD | E21: USA | F21: North America | G21: Technology | H21: Semiconductors | I21: NASDAQ | J21: 1969 | K21: 31000 | L21: 764.34 | M21: 0.76434 | N21: 37.45 | O21: 0.1195 | P21: 46265 | Q21: https://companiesmarketcap.com/amd/ | R21: Official company annual report / investor-relations disclosure (latest completed annual disclosure retained from prior enrichment) | S21: 31 Aug 2026 market-cap snapshot + current TTM operating margin + latest annual/company disclosure | T21: https://companiesmarketcap.com/amd/operating-margin/
A22: 20 | B22: MC-020 | C22: Visa | D22: V | E22: USA | F22: North America | G22: Financials | H22: Financial services | I22: NYSE | J22: 1958 | K22: 34100 | L22: 709.08 | M22: 0.70908 | N22: 43.02 | O22: 0.6148 | P22: 46265 | Q22: https://companiesmarketcap.com/visa/ | R22: Official company annual report / investor-relations disclosure (latest completed annual disclosure retained from prior enrichment) | S22: 31 Aug 2026 market-cap snapshot + current TTM operating margin + latest annual/company disclosure | T22: https://companiesmarketcap.com/visa/operating-margin/
A23: 21 | B23: MC-021 | C23: Exxon Mobil | D23: XOM | E23: USA | F23: North America | G23: Energy | H23: Oil&Gas | I23: NYSE | J23: 1870 | K23: 58000 | L23: 659.26 | M23: 0.65926 | N23: 326 | O23: 0.1123 | P23: 46265 | Q23: https://companiesmarketcap.com/exxon-mobil/ | R23: Official company annual report / investor-relations disclosure (latest completed annual disclosure retained from prior enrichment) | S23: 31 Aug 2026 market-cap snapshot + current TTM operating margin + latest annual/company disclosure | T23: https://companiesmarketcap.com/exxon-mobil/operating-margin/
A24: 22 | B24: MC-022 | C24: ASML | D24: ASML | E24: Netherlands | F24: Europe | G24: Technology | H24: Semiconductors | I24: NASDAQ / Euronext Amsterdam | J24: 1984 | K24: 44175 | L24: 649.33 | M24: 0.64933 | N24: 41.02 | O24: 0.3491 | P24: 46265 | Q24: https://companiesmarketcap.com/asml/ | R24: Official company annual report / investor-relations disclosure (latest completed annual disclosure retained from prior enrichment) | S24: 31 Aug 2026 market-cap snapshot + current TTM operating margin + latest annual/company disclosure | T24: https://companiesmarketcap.com/asml/operating-margin/
A25: 23 | B25: MC-023 | C25: Johnson & Johnson | D25: JNJ | E25: USA | F25: North America | G25: Technology | H25: Pharmaceuticals | I25: NYSE | J25: 1886 | K25: 138200 | L25: 641.34 | M25: 0.64134 | N25: 96.36 | O25: 0.3458 | P25: 46265 | Q25: https://companiesmarketcap.com/johnson-and-johnson/ | R25: Official company annual report / investor-relations disclosure (latest completed annual disclosure retained from prior enrichment) | S25: 31 Aug 2026 market-cap snapshot + current TTM operating margin + latest annual/company disclosure | T25: https://companiesmarketcap.com/johnson-and-johnson/operating-margin/
A26: 24 | B26: MC-024 | C26: CXMT | D26: 688825.SS | E26: China | F26: Asia-Pacific | G26: Technology | H26: Semiconductors | I26: Shanghai Stock Exchange | J26: 2016 | K26: Not separately stated in latest annual disclosure | L26: 611.37 | M26: 0.61137 | N26: 15.24 | O26: 0.4319 | P26: 46265 | Q26: https://companiesmarketcap.com/cxmt/ | R26: Official company annual report / investor-relations disclosure (latest completed annual disclosure retained from prior enrichment) | S26: 31 Aug 2026 market-cap snapshot + current TTM operating margin + latest annual/company disclosure | T26: https://companiesmarketcap.com/cxmt/operating-margin/
A27: 25 | B27: MC-025 | C27: Tencent | D27: TCEHY | E27: China | F27: Asia-Pacific | G27: Technology | H27: Internet | I27: OTC / Hong Kong Stock Exchange | J27: 1998 | K27: 87412 | L27: 516.34 | M27: 0.51634 | N27: 111.76 | O27: 0.3687 | P27: 46265 | Q27: https://companiesmarketcap.com/tencent/ | R27: Official company annual report / investor-relations disclosure (latest completed annual disclosure retained from prior enrichment) | S27: 31 Aug 2026 market-cap snapshot + current TTM operating margin + latest annual/company disclosure | T27: https://companiesmarketcap.com/tencent/operating-margin/
A28: 26 | B28: MC-026 | C28: Mastercard | D28: MA | E28: USA | F28: North America | G28: Financials | H28: Financial services | I28: NYSE | J28: 1966 | K28: 39800 | L28: 515.75 | M28: 0.51575 | N28: 33.93 | O28: 0.5704 | P28: 46265 | Q28: https://companiesmarketcap.com/mastercard/ | R28: Official company annual report / investor-relations disclosure (latest completed annual disclosure retained from prior enrichment) | S28: 31 Aug 2026 market-cap snapshot + current TTM operating margin + latest annual/company disclosure | T28: https://companiesmarketcap.com/mastercard/operating-margin/
A29: 27 | B29: MC-027 | C29: Intel | D29: INTC | E29: USA | F29: North America | G29: Technology | H29: Semiconductors | I29: NASDAQ | J29: 1968 | K29: 85100 | L29: 472.57 | M29: 0.47257 | N29: 53.76 | O29: 0.0294 | P29: 46265 | Q29: https://companiesmarketcap.com/intel/ | R29: Official company annual report / investor-relations disclosure (latest completed annual disclosure retained from prior enrichment) | S29: 31 Aug 2026 market-cap snapshot + current TTM operating margin + latest annual/company disclosure | T29: https://companiesmarketcap.com/intel/operating-margin/
A30: 28 | B30: MC-028 | C30: AbbVie | D30: ABBV | E30: USA | F30: North America | G30: Technology | H30: Pharmaceuticals | I30: NYSE | J30: 2013 | K30: 57000 | L30: 455.42 | M30: 0.45542 | N30: 62.81 | O30: 0.0951 | P30: 46265 | Q30: https://companiesmarketcap.com/abbvie/ | R30: Official company annual report / investor-relations disclosure (latest completed annual disclosure retained from prior enrichment) | S30: 31 Aug 2026 market-cap snapshot + current TTM operating margin + latest annual/company disclosure | T30: https://companiesmarketcap.com/abbvie/operating-margin/
A31: 29 | B31: MC-029 | C31: Palantir | D31: PLTR | E31: USA | F31: North America | G31: Technology | H31: Software | I31: NASDAQ | J31: 2003 | K31: 4429 | L31: 449.94 | M31: 0.44994 | N31: 5.22 | O31: 0.4445 | P31: 46265 | Q31: https://companiesmarketcap.com/palantir/ | R31: Official company annual report / investor-relations disclosure (latest completed annual disclosure retained from prior enrichment) | S31: 31 Aug 2026 market-cap snapshot + current TTM operating margin + latest annual/company disclosure | T31: https://companiesmarketcap.com/palantir/operating-margin/
A32: 30 | B32: MC-030 | C32: Cisco | D32: CSCO | E32: USA | F32: North America | G32: Technology | H32: Tech | I32: NASDAQ | J32: 1984 | K32: 86200 | L32: 436.49 | M32: 0.43649 | N32: 60.74 | O32: 0.1959 | P32: 46265 | Q32: https://companiesmarketcap.com/cisco/ | R32: Official company annual report / investor-relations disclosure (latest completed annual disclosure retained from prior enrichment) | S32: 31 Aug 2026 market-cap snapshot + current TTM operating margin + latest annual/company disclosure | T32: https://companiesmarketcap.com/cisco/operating-margin/
A33: 31 | B33: MC-031 | C33: Bank of America | D33: BAC | E33: USA | F33: North America | G33: Financials | H33: Banks | I33: NYSE | J33: 1784 | K33: 213000 | L33: 432.95 | M33: 0.43295 | N33: 116 | O33: 0.3446 | P33: 46265 | Q33: https://companiesmarketcap.com/bank-of-america/ | R33: Official company annual report / investor-relations disclosure (latest completed annual disclosure retained from prior enrichment) | S33: 31 Aug 2026 market-cap snapshot + current TTM operating margin + latest annual/company disclosure | T33: https://companiesmarketcap.com/bank-of-america/operating-margin/
A34: 32 | B34: MC-032 | C34: Oracle | D34: ORCL | E34: USA | F34: North America | G34: Technology | H34: Software | I34: NYSE | J34: 1977 | K34: 141000 | L34: 431.29 | M34: 0.43129 | N34: 67.35 | O34: 0.2903 | P34: 46265 | Q34: https://companiesmarketcap.com/oracle/ | R34: Official company annual report / investor-relations disclosure (latest completed annual disclosure retained from prior enrichment) | S34: 31 Aug 2026 market-cap snapshot + current TTM operating margin + latest annual/company disclosure | T34: https://companiesmarketcap.com/oracle/operating-margin/
A35: 33 | B35: MC-033 | C35: China Construction Bank | D35: 601939.SS | E35: China | F35: Asia-Pacific | G35: Financials | H35: Banks | I35: Shanghai / Hong Kong | J35: 1954 | K35: 378344 | L35: 427.48 | M35: 0.42748 | N35: 112.1 | O35: 0.47 | P35: 46265 | Q35: https://companiesmarketcap.com/china-construction-bank/ | R35: Official company annual report / investor-relations disclosure (latest completed annual disclosure retained from prior enrichment) | S35: 31 Aug 2026 market-cap snapshot + current TTM operating margin + latest annual/company disclosure | T35: https://companiesmarketcap.com/china-construction-bank/operating-margin/
A36: 34 | B36: MC-034 | C36: Costco | D36: COST | E36: USA | F36: North America | G36: Consumer Discretionary | H36: Retail | I36: NASDAQ | J36: 1983 | K36: 341000 | L36: 418.36 | M36: 0.41836 | N36: 293.58 | O36: 0.0393 | P36: 46265 | Q36: https://companiesmarketcap.com/costco/ | R36: Official company annual report / investor-relations disclosure (latest completed annual disclosure retained from prior enrichment) | S36: 31 Aug 2026 market-cap snapshot + current TTM operating margin + latest annual/company disclosure | T36: https://companiesmarketcap.com/costco/operating-margin/
A37: 35 | B37: MC-035 | C37: Chevron | D37: CVX | E37: USA | F37: North America | G37: Energy | H37: Oil&Gas | I37: NYSE | J37: 1879 | K37: 43039 | L37: 403.25 | M37: 0.40325 | N37: 185.88 | O37: 0.1046 | P37: 46265 | Q37: https://companiesmarketcap.com/chevron/ | R37: Official company annual report / investor-relations disclosure (latest completed annual disclosure retained from prior enrichment) | S37: 31 Aug 2026 market-cap snapshot + current TTM operating margin + latest annual/company disclosure | T37: https://companiesmarketcap.com/chevron/operating-margin/
A38: 36 | B38: MC-036 | C38: Coca-Cola | D38: KO | E38: USA | F38: North America | G38: Consumer Staples | H38: Beverages | I38: NYSE | J38: 1886 | K38: 65900 | L38: 382.15 | M38: 0.38215 | N38: 49.28 | O38: 0.3337 | P38: 46265 | Q38: https://companiesmarketcap.com/coca-cola/ | R38: Official company annual report / investor-relations disclosure (latest completed annual disclosure retained from prior enrichment) | S38: 31 Aug 2026 market-cap snapshot + current TTM operating margin + latest annual/company disclosure | T38: https://companiesmarketcap.com/coca-cola/operating-margin/
... A47: 45 | B47: MC-045 | C47: General Electric | D47: GE | E47: USA | F47: North America | G47: Industrials | H47: Aerospace | I47: NYSE | J47: 1892 | K47: 57000 | L47: 348.6 | M47: 0.3486 | N47: 50.63 | O47: 0.218 | P47: 46265 | Q47: https://companiesmarketcap.com/general-electric/ | R47: Official company annual report / investor-relations disclosure (latest completed annual disclosure retained from prior enrichment) | S47: 31 Aug 2026 market-cap snapshot + current TTM operating margin + latest annual/company disclosure | T47: https://companiesmarketcap.com/general-electric/operating-margin/
A48: 46 | B48: MC-046 | C48: ICBC | D48: 1398.HK | E48: China | F48: Asia-Pacific | G48: Financials | H48: Banks | I48: Hong Kong / Shanghai | J48: 1984 | K48: Not separately stated in latest annual disclosure | L48: 344.19 | M48: 0.34419 | N48: 120.28 | O48: Current TTM operating margin not available from source | P48: 46265 | Q48: https://companiesmarketcap.com/icbc/ | R48: Official company annual report / investor-relations disclosure (latest completed annual disclosure retained from prior enrichment) | S48: 31 Aug 2026 market-cap snapshot + latest annual/company disclosure; margin excluded from relationship analysis | T48: https://companiesmarketcap.com/icbc/operating-margin/
...

Sheet Pivot Analysis
A1: MARKET-CAP ANALYSIS | SECTOR, REGION AND COUNTRY SUMMARIES
A3: Sector | B3: Company Count | C3: Market Cap (USD bn) | D3: Market Cap Share | F3: Region | G3: Company Count | H3: Market Cap (USD bn) | I3: Market Cap Share
A4: Communication Services | B4: =COUNTIF('Top 100 Market Cap'!$G$3:$G$102,A4) -> 3 | C4: =SUMIF('Top 100 Market Cap'!$G$3:$G$102,A4,'Top 100 Market Cap'!$L$3:$L$102) -> 622.03 | D4: =C4/SUM('Top 100 Market Cap'!$L$3:$L$102) -> 0.0096669237 | F4: Asia-Pacific | G4: =COUNTIF('Top 100 Market Cap'!$F$3:$F$102,F4) -> 18 | H4: =SUMIF('Top 100 Market Cap'!$F$3:$F$102,F4,'Top 100 Market Cap'!$L$3:$L$102) -> 9002.01 | I4: =H4/SUM('Top 100 Market Cap'!$L$3:$L$102) -> 0.13989959
A5: Consumer Discretionary | B5: =COUNTIF('Top 100 Market Cap'!$G$3:$G$102,A5) -> 7 | C5: =SUMIF('Top 100 Market Cap'!$G$3:$G$102,A5,'Top 100 Market Cap'!$L$3:$L$102) -> 2627.27 | D5: =C5/SUM('Top 100 Market Cap'!$L$3:$L$102) -> 0.040830215 | F5: Europe | G5: =COUNTIF('Top 100 Market Cap'!$F$3:$F$102,F5) -> 19 | H5: =SUMIF('Top 100 Market Cap'!$F$3:$F$102,F5,'Top 100 Market Cap'!$L$3:$L$102) -> 5108.43 | I5: =H5/SUM('Top 100 Market Cap'!$L$3:$L$102) -> 0.079389745
A6: Consumer Staples | B6: =COUNTIF('Top 100 Market Cap'!$G$3:$G$102,A6) -> 4 | C6: =SUMIF('Top 100 Market Cap'!$G$3:$G$102,A6,'Top 100 Market Cap'!$L$3:$L$102) -> 1168.26 | D6: =C6/SUM('Top 100 Market Cap'!$L$3:$L$102) -> 0.018155845 | F6: Middle East & Africa | G6: =COUNTIF('Top 100 Market Cap'!$F$3:$F$102,F6) -> 2 | H6: =SUMIF('Top 100 Market Cap'!$F$3:$F$102,F6,'Top 100 Market Cap'!$L$3:$L$102) -> 1899.99 | I6: =H6/SUM('Top 100 Market Cap'!$L$3:$L$102) -> 0.029527609
A7: Energy | B7: =COUNTIF('Top 100 Market Cap'!$G$3:$G$102,A7) -> 7 | C7: =SUMIF('Top 100 Market Cap'!$G$3:$G$102,A7,'Top 100 Market Cap'!$L$3:$L$102) -> 3663.42 | D7: =C7/SUM('Top 100 Market Cap'!$L$3:$L$102) -> 0.056932948 | F7: North America | G7: =COUNTIF('Top 100 Market Cap'!$F$3:$F$102,F7) -> 61 | H7: =SUMIF('Top 100 Market Cap'!$F$3:$F$102,F7,'Top 100 Market Cap'!$L$3:$L$102) -> 48335.79 | I7: =H7/SUM('Top 100 Market Cap'!$L$3:$L$102) -> 0.75118305
A8: Financials | B8: =COUNTIF('Top 100 Market Cap'!$G$3:$G$102,A8) -> 23 | C8: =SUMIF('Top 100 Market Cap'!$G$3:$G$102,A8,'Top 100 Market Cap'!$L$3:$L$102) -> 8731.2 | D8: =C8/SUM('Top 100 Market Cap'!$L$3:$L$102) -> 0.13569095
A9: Industrials | B9: =COUNTIF('Top 100 Market Cap'!$G$3:$G$102,A9) -> 3 | C9: =SUMIF('Top 100 Market Cap'!$G$3:$G$102,A9,'Top 100 Market Cap'!$L$3:$L$102) -> 888.9 | D9: =C9/SUM('Top 100 Market Cap'!$L$3:$L$102) -> 0.013814331
A10: Materials | B10: =COUNTIF('Top 100 Market Cap'!$G$3:$G$102,A10) -> 2 | C10: =SUMIF('Top 100 Market Cap'!$G$3:$G$102,A10,'Top 100 Market Cap'!$L$3:$L$102) -> 463.84 | D10: =C10/SUM('Top 100 Market Cap'!$L$3:$L$102) -> 0.0072085042
A11: Other | B11: =COUNTIF('Top 100 Market Cap'!$G$3:$G$102,A11) -> 2 | C11: =SUMIF('Top 100 Market Cap'!$G$3:$G$102,A11,'Top 100 Market Cap'!$L$3:$L$102) -> 598.52 | D11: =C11/SUM('Top 100 Market Cap'!$L$3:$L$102) -> 0.0093015565
A12: Technology | B12: =COUNTIF('Top 100 Market Cap'!$G$3:$G$102,A12) -> 48 | C12: =SUMIF('Top 100 Market Cap'!$G$3:$G$102,A12,'Top 100 Market Cap'!$L$3:$L$102) -> 45332.45 | D12: =C12/SUM('Top 100 Market Cap'!$L$3:$L$102) -> 0.70450836
A13: Utilities | B13: =COUNTIF('Top 100 Market Cap'!$G$3:$G$102,A13) -> 1 | C13: =SUMIF('Top 100 Market Cap'!$G$3:$G$102,A13,'Top 100 Market Cap'!$L$3:$L$102) -> 250.33 | D13: =C13/SUM('Top 100 Market Cap'!$L$3:$L$102) -> 0.0038903606
A16: Country | B16: Company Count | C16: Market Cap (USD bn) | D16: Market Cap Share
A17: Australia | B17: =COUNTIF('Top 100 Market Cap'!$E$3:$E$102,A17) -> 1 | C17: =SUMIF('Top 100 Market Cap'!$E$3:$E$102,A17,'Top 100 Market Cap'!$L$3:$L$102) -> 238.54 | D17: =C17/SUM('Top 100 Market Cap'!$L$3:$L$102) -> 0.0037071331
A18: Canada | B18: =COUNTIF('Top 100 Market Cap'!$E$3:$E$102,A18) -> 2 | C18: =SUMIF('Top 100 Market Cap'!$E$3:$E$102,A18,'Top 100 Market Cap'!$L$3:$L$102) -> 480.18 | D18: =C18/SUM('Top 100 Market Cap'!$L$3:$L$102) -> 0.007462443
A19: China | B19: =COUNTIF('Top 100 Market Cap'!$E$3:$E$102,A19) -> 11 | C19: =SUMIF('Top 100 Market Cap'!$E$3:$E$102,A19,'Top 100 Market Cap'!$L$3:$L$102) -> 3805.4 | D19: =C19/SUM('Top 100 Market Cap'!$L$3:$L$102) -> 0.059139449
A20: Denmark | B20: =COUNTIF('Top 100 Market Cap'!$E$3:$E$102,A20) -> 1 | C20: =SUMIF('Top 100 Market Cap'!$E$3:$E$102,A20,'Top 100 Market Cap'!$L$3:$L$102) -> 200.31 | D20: =C20/SUM('Top 100 Market Cap'!$L$3:$L$102) -> 0.0031130034
A21: France | B21: =COUNTIF('Top 100 Market Cap'!$E$3:$E$102,A21) -> 3 | C21: =SUMIF('Top 100 Market Cap'!$E$3:$E$102,A21,'Top 100 Market Cap'!$L$3:$L$102) -> 693.09 | D21: =C21/SUM('Top 100 Market Cap'!$L$3:$L$102) -> 0.010771262
A22: Germany | B22: =COUNTIF('Top 100 Market Cap'!$E$3:$E$102,A22) -> 3 | C22: =SUMIF('Top 100 Market Cap'!$E$3:$E$102,A22,'Top 100 Market Cap'!$L$3:$L$102) -> 713.65 | D22: =C22/SUM('Top 100 Market Cap'!$L$3:$L$102) -> 0.011090784
A23: Japan | B23: =COUNTIF('Top 100 Market Cap'!$E$3:$E$102,A23) -> 2 | C23: =SUMIF('Top 100 Market Cap'!$E$3:$E$102,A23,'Top 100 Market Cap'!$L$3:$L$102) -> 488.55 | D23: =C23/SUM('Top 100 Market Cap'!$L$3:$L$102) -> 0.0075925206
A24: Netherlands | B24: =COUNTIF('Top 100 Market Cap'!$E$3:$E$102,A24) -> 2 | C24: =SUMIF('Top 100 Market Cap'!$E$3:$E$102,A24,'Top 100 Market Cap'!$L$3:$L$102) -> 843.91 | D24: =C24/SUM('Top 100 Market Cap'!$L$3:$L$102) -> 0.013115145
A25: S. Arabia | B25: =COUNTIF('Top 100 Market Cap'!$E$3:$E$102,A25) -> 1 | C25: =SUMIF('Top 100 Market Cap'!$E$3:$E$102,A25,'Top 100 Market Cap'!$L$3:$L$102) -> 1679 | D25: =C25/SUM('Top 100 Market Cap'!$L$3:$L$102) -> 0.026093219
A26: S. Korea | B26: =COUNTIF('Top 100 Market Cap'!$E$3:$E$102,A26) -> 2 | C26: =SUMIF('Top 100 Market Cap'!$E$3:$E$102,A26,'Top 100 Market Cap'!$L$3:$L$102) -> 2116.67 | D26: =C26/SUM('Top 100 Market Cap'!$L$3:$L$102) -> 0.032895017
A27: Spain | B27: =COUNTIF('Top 100 Market Cap'!$E$3:$E$102,A27) -> 2 | C27: =SUMIF('Top 100 Market Cap'!$E$3:$E$102,A27,'Top 100 Market Cap'!$L$3:$L$102) -> 422.55 | D27: =C27/SUM('Top 100 Market Cap'!$L$3:$L$102) -> 0.0065668193
A28: Switzerland | B28: =COUNTIF('Top 100 Market Cap'!$E$3:$E$102,A28) -> 3 | C28: =SUMIF('Top 100 Market Cap'!$E$3:$E$102,A28,'Top 100 Market Cap'!$L$3:$L$102) -> 895.6 | D28: =C28/SUM('Top 100 Market Cap'!$L$3:$L$102) -> 0.013918456
... A32: USA | B32: =COUNTIF('Top 100 Market Cap'!$E$3:$E$102,A32) -> 59 | C32: =SUMIF('Top 100 Market Cap'!$E$3:$E$102,A32,'Top 100 Market Cap'!$L$3:$L$102) -> 47855.61 | D32: =C32/SUM('Top 100 Market Cap'!$L$3:$L$102) -> 0.74372061

Sheet Dashboard
A1: DASHBOARD
A2: WORLD TOP 100 COMPANIES BY MARKET CAPITALISATION
A3: Companies | C3: Total Market Cap | E3: Largest Company | G3: Median Market Cap | I3: USA Companies | K3: Mkt Cap vs Margin
A4: =COUNTA('Top 100 Market Cap'!A3:A102) -> 100 | C4: =SUM('Top 100 Market Cap'!L3:L102)/1000 -> 64.34622 | E4: NVIDIA | F4: =MAX('Top 100 Market Cap'!L3:L102)/1000 -> 5.306 | G4: =MEDIAN('Top 100 Market Cap'!L3:L102) -> 319.72 | I4: =COUNTIF('Top 100 Market Cap'!E3:E102,"USA") -> 59 | K4: ="Weak positive (r="&TEXT('Relationship Analysis'!B5,"0.000")&")" -> Weak positive (r=0.282)
A7: Rank | B7: Company | C7: Market Cap (USD bn) | E7: Sector | F7: Companies | G7: Market Cap (USD bn)
A8: 1 | B8: NVIDIA | C8: 5306 | E8: Communication Services | F8: =COUNTIF('Top 100 Market Cap'!$G$3:$G$102,E8) -> 3 | G8: =SUMIF('Top 100 Market Cap'!$G$3:$G$102,E8,'Top 100 Market Cap'!$L$3:$L$102) -> 622.03
A9: 2 | B9: Apple | C9: 4609 | E9: Consumer Discretionary | F9: =COUNTIF('Top 100 Market Cap'!$G$3:$G$102,E9) -> 7 | G9: =SUMIF('Top 100 Market Cap'!$G$3:$G$102,E9,'Top 100 Market Cap'!$L$3:$L$102) -> 2627.27
A10: 3 | B10: Alphabet (Google) | C10: 4096 | E10: Consumer Staples | F10: =COUNTIF('Top 100 Market Cap'!$G$3:$G$102,E10) -> 4 | G10: =SUMIF('Top 100 Market Cap'!$G$3:$G$102,E10,'Top 100 Market Cap'!$L$3:$L$102) -> 1168.26
A11: 4 | B11: Microsoft | C11: 3783 | E11: Energy | F11: =COUNTIF('Top 100 Market Cap'!$G$3:$G$102,E11) -> 7 | G11: =SUMIF('Top 100 Market Cap'!$G$3:$G$102,E11,'Top 100 Market Cap'!$L$3:$L$102) -> 3663.42
A12: 5 | B12: Amazon | C12: 2794 | E12: Financials | F12: =COUNTIF('Top 100 Market Cap'!$G$3:$G$102,E12) -> 23 | G12: =SUMIF('Top 100 Market Cap'!$G$3:$G$102,E12,'Top 100 Market Cap'!$L$3:$L$102) -> 8731.2
A13: 6 | B13: TSMC | C13: 2155 | E13: Industrials | F13: =COUNTIF('Top 100 Market Cap'!$G$3:$G$102,E13) -> 3 | G13: =SUMIF('Top 100 Market Cap'!$G$3:$G$102,E13,'Top 100 Market Cap'!$L$3:$L$102) -> 888.9
A14: 7 | B14: SpaceX | C14: 1876 | E14: Materials | F14: =COUNTIF('Top 100 Market Cap'!$G$3:$G$102,E14) -> 2 | G14: =SUMIF('Top 100 Market Cap'!$G$3:$G$102,E14,'Top 100 Market Cap'!$L$3:$L$102) -> 463.84
A15: 8 | B15: Broadcom | C15: 1757 | E15: Other | F15: =COUNTIF('Top 100 Market Cap'!$G$3:$G$102,E15) -> 2 | G15: =SUMIF('Top 100 Market Cap'!$G$3:$G$102,E15,'Top 100 Market Cap'!$L$3:$L$102) -> 598.52
A16: 9 | B16: Saudi Aramco | C16: 1679 | E16: Technology | F16: =COUNTIF('Top 100 Market Cap'!$G$3:$G$102,E16) -> 48 | G16: =SUMIF('Top 100 Market Cap'!$G$3:$G$102,E16,'Top 100 Market Cap'!$L$3:$L$102) -> 45332.45
A17: 10 | B17: Meta Platforms (Facebook) | C17: 1457 | E17: Utilities | F17: =COUNTIF('Top 100 Market Cap'!$G$3:$G$102,E17) -> 1 | G17: =SUMIF('Top 100 Market Cap'!$G$3:$G$102,E17,'Top 100 Market Cap'!$L$3:$L$102) -> 250.33
A20: MARKET CAP VS PROFIT MARGIN % RELATIONSHIP
A21: Matched companies | B21: Pearson r | C21: R-squared | D21: Interpretation
A22: ='Relationship Analysis'!A5 -> 95 | B22: ='Relationship Analysis'!B5 -> 0.28231383 | C22: ='Relationship Analysis'!C5 -> 0.079701098 | D22: ='Relationship Analysis'!D5 -> Weak positive
A23: ="Finding: "&D22&" relationship. Market cap explains about "&TEXT(C22,"0.0%")&" of the variation in operating profit margin among matched companies." -> Finding: Weak positive relationship. Market cap explains about 8.0% of the variation in operating profit margin among matched companies.
A36: KEY READING
A37: The Top 100 is highly concentrated in mega-cap technology companies and the United States remains the largest country presence. The market-cap versus operating profit margin analysis shows only a weak positive relationship, so larger company size does not strongly predict a higher operating margin. Annual revenue and employee figures provide scale context, while market capitalisation remains a point-in-time measure that changes with market prices.

Sheet Relationship Analysis
A1: RELATIONSHIP BETWEEN MARKET CAPITALISATION AND OPERATING PROFIT MARGIN
A2: Same-company analysis for the World Top 100 by market capitalisation. Companies without a current numeric TTM operating margin are excluded from the correlation.
A4: Matched Companies | B4: Pearson Correlation (r) | C4: R-squared | D4: Direction / Strength | E4: Largest Market Cap | F4: Highest Margin | G4: Lowest Margin | H4: Excluded
A5: =COUNT(B9:B103) -> 95 | B5: =CORREL(B9:B103,C9:C103) -> 0.28231383 | C5: =B5^2 -> 0.079701098 | D5: =IF(ABS(B5)<0.2,"Very weak "&IF(B5>=0,"positive","negative"),IF(ABS(B5)<0.4,"Weak "&IF(B5>=0,"positive","negative"),IF(ABS(B5)<0.6,"Moderate "&IF(B5>=0,"positive","negative"),IF(ABS(B5)<0.8,"Strong "&IF(B5>=0,"positive","negative"),"Very strong "&IF(B5>=0,"positive","negative"))))) -> Weak positive | E5: =MAX(B9:B103) -> 5306 | F5: =MAX(C9:C103) -> 0.7485 | G5: =MIN(C9:C103) -> -0.2259 | H5: 5
A8: Company | B8: Market Cap (USD bn) | C8: Operating Margin (TTM) | D8: Sector | E8: Source | G8: How to read the result
A9: ='Top 100 Market Cap'!C3 -> NVIDIA | B9: ='Top 100 Market Cap'!L3 -> 5306 | C9: ='Top 100 Market Cap'!O3 -> 0.7485 | D9: ='Top 100 Market Cap'!G3 -> Technology | E9: ='Top 100 Market Cap'!T3 -> https://companiesmarketcap.com/nvidia/operating-margin/ | G9: ="Pearson r = "&TEXT(B5,"0.000")&". This indicates a "&LOWER(D5)&" relationship between market capitalisation and operating profit margin in the matched Top 100 companies. "&"R-squared = "&TEXT(C5,"0.0%")&", so market capitalisation alone explains only about "&TEXT(C5,"0.0%")&" of the observed variation in operating margin. Correlation does not imply causation." -> Pearson r = 0.282. This indicates a weak positive relationship between market capitalisation and operating profit margin in the matched Top 100 companies. R-squared = 8.0%, so market capitalisation alone explains only about 8.0% of the observed variation in operating margin. Correlation does not imply causation.
A10: ='Top 100 Market Cap'!C4 -> Apple | B10: ='Top 100 Market Cap'!L4 -> 4609 | C10: ='Top 100 Market Cap'!O4 -> 0.3189 | D10: ='Top 100 Market Cap'!G4 -> Technology | E10: ='Top 100 Market Cap'!T4 -> https://companiesmarketcap.com/apple/operating-margin/
A11: ='Top 100 Market Cap'!C5 -> Alphabet (Google) | B11: ='Top 100 Market Cap'!L5 -> 4096 | C11: ='Top 100 Market Cap'!O5 -> 0.4631 | D11: ='Top 100 Market Cap'!G5 -> Technology | E11: ='Top 100 Market Cap'!T5 -> https://companiesmarketcap.com/alphabet-google/operating-margin/
A12: ='Top 100 Market Cap'!C6 -> Microsoft | B12: ='Top 100 Market Cap'!L6 -> 3783 | C12: ='Top 100 Market Cap'!O6 -> 0.4854 | D12: ='Top 100 Market Cap'!G6 -> Technology | E12: ='Top 100 Market Cap'!T6 -> https://companiesmarketcap.com/microsoft/operating-margin/
A13: ='Top 100 Market Cap'!C7 -> Amazon | B13: ='Top 100 Market Cap'!L7 -> 2794 | C13: ='Top 100 Market Cap'!O7 -> 0.1357 | D13: ='Top 100 Market Cap'!G7 -> Technology | E13: ='Top 100 Market Cap'!T7 -> https://companiesmarketcap.com/amazon/operating-margin/
A14: ='Top 100 Market Cap'!C8 -> TSMC | B14: ='Top 100 Market Cap'!L8 -> 2155 | C14: ='Top 100 Market Cap'!O8 -> 0.536 | D14: ='Top 100 Market Cap'!G8 -> Technology | E14: ='Top 100 Market Cap'!T8 -> https://companiesmarketcap.com/tsmc/operating-margin/
A15: ='Top 100 Market Cap'!C9 -> SpaceX | B15: ='Top 100 Market Cap'!L9 -> 1876 | C15: ='Top 100 Market Cap'!O9 -> -0.2259 | D15: ='Top 100 Market Cap'!G9 -> Technology | E15: ='Top 100 Market Cap'!T9 -> https://companiesmarketcap.com/spacex/operating-margin/
A16: ='Top 100 Market Cap'!C10 -> Broadcom | B16: ='Top 100 Market Cap'!L10 -> 1757 | C16: ='Top 100 Market Cap'!O10 -> 0.4455 | D16: ='Top 100 Market Cap'!G10 -> Technology | E16: ='Top 100 Market Cap'!T10 -> https://companiesmarketcap.com/broadcom/operating-margin/
A17: ='Top 100 Market Cap'!C11 -> Saudi Aramco | B17: ='Top 100 Market Cap'!L11 -> 1679 | C17: ='Top 100 Market Cap'!O11 -> 0.4247 | D17: ='Top 100 Market Cap'!G11 -> Energy | E17: ='Top 100 Market Cap'!T11 -> https://companiesmarketcap.com/saudi-aramco/operating-margin/
A18: ='Top 100 Market Cap'!C12 -> Meta Platforms (Facebook) | B18: ='Top 100 Market Cap'!L12 -> 1457 | C18: ='Top 100 Market Cap'!O12 -> 0.4223 | D18: ='Top 100 Market Cap'!G12 -> Technology | E18: ='Top 100 Market Cap'!T12 -> https://companiesmarketcap.com/meta-platforms/operating-margin/
A19: ='Top 100 Market Cap'!C13 -> Tesla | B19: ='Top 100 Market Cap'!L13 -> 1448 | C19: ='Top 100 Market Cap'!O13 -> 0.059 | D19: ='Top 100 Market Cap'!G13 -> Technology | E19: ='Top 100 Market Cap'!T13 -> https://companiesmarketcap.com/tesla/operating-margin/
A20: ='Top 100 Market Cap'!C14 -> Samsung | B20: ='Top 100 Market Cap'!L14 -> 1248 | C20: ='Top 100 Market Cap'!O14 -> 0.2553 | D20: ='Top 100 Market Cap'!G14 -> Technology | E20: ='Top 100 Market Cap'!T14 -> https://companiesmarketcap.com/samsung/operating-margin/
A21: ='Top 100 Market Cap'!C15 -> Berkshire Hathaway | B21: ='Top 100 Market Cap'!L15 -> 1078 | C21: ='Top 100 Market Cap'!O15 -> 0.1601 | D21: ='Top 100 Market Cap'!G15 -> Financials | E21: ='Top 100 Market Cap'!T15 -> https://companiesmarketcap.com/berkshire-hathaway/operating-margin/
... A53: ='Top 100 Market Cap'!C47 -> General Electric | B53: ='Top 100 Market Cap'!L47 -> 348.6 | C53: ='Top 100 Market Cap'!O47 -> 0.218 | D53: ='Top 100 Market Cap'!G47 -> Industrials | E53: ='Top 100 Market Cap'!T47 -> https://companiesmarketcap.com/general-electric/operating-margin/
A54: ='Top 100 Market Cap'!C49 -> Netflix | B54: ='Top 100 Market Cap'!L49 -> 338.75 | C54: ='Top 100 Market Cap'!O49 -> 0.2815 | D54: ='Top 100 Market Cap'!G49 -> Technology | E54: ='Top 100 Market Cap'!T49 -> https://companiesmarketcap.com/netflix/operating-margin/
A55: ='Top 100 Market Cap'!C50 -> Procter & Gamble | B55: ='Top 100 Market Cap'!L50 -> 338.11 | C55: ='Top 100 Market Cap'!O50 -> 0.2392 | D55: ='Top 100 Market Cap'!G50 -> Consumer Discretionary | E55: ='Top 100 Market Cap'!T50 -> https://companiesmarketcap.com/procter-and-gamble/operating-margin/
A56: ='Top 100 Market Cap'!C51 -> Morgan Stanley | B56: ='Top 100 Market Cap'!L51 -> 335.23 | C56: ='Top 100 Market Cap'!O51 -> 0.3405 | D56: ='Top 100 Market Cap'!G51 -> Financials | E56: ='Top 100 Market Cap'!T51 -> https://companiesmarketcap.com/morgan-stanley/operating-margin/
A57: ='Top 100 Market Cap'!C52 -> Home Depot | B57: ='Top 100 Market Cap'!L52 -> 327.26 | C57: ='Top 100 Market Cap'!O52 -> 0.1129 | D57: ='Top 100 Market Cap'!G52 -> Consumer Discretionary | E57: ='Top 100 Market Cap'!T52 -> https://companiesmarketcap.com/home-depot/operating-margin/
A58: ='Top 100 Market Cap'!C53 -> Bank of China | B58: ='Top 100 Market Cap'!L53 -> 312.18 | C58: ='Top 100 Market Cap'!O53 -> 0.4509 | D58: ='Top 100 Market Cap'!G53 -> Financials | E58: ='Top 100 Market Cap'!T53 -> https://companiesmarketcap.com/bank-of-china/operating-margin/
A59: ='Top 100 Market Cap'!C54 -> Palo Alto Networks | B59: ='Top 100 Market Cap'!L54 -> 310.84 | C59: ='Top 100 Market Cap'!O54 -> 0.1317 | D59: ='Top 100 Market Cap'!G54 -> Technology | E59: ='Top 100 Market Cap'!T54 -> https://companiesmarketcap.com/palo-alto-networks/operating-margin/
A60: ='Top 100 Market Cap'!C55 -> Dell | B60: ='Top 100 Market Cap'!L55 -> 300.17 | C60: ='Top 100 Market Cap'!O55 -> 0.0875 | D60: ='Top 100 Market Cap'!G55 -> Technology | E60: ='Top 100 Market Cap'!T55 -> https://companiesmarketcap.com/dell/operating-margin/
A61: ='Top 100 Market Cap'!C56 -> Goldman Sachs | B61: ='Top 100 Market Cap'!L56 -> 298.99 | C61: ='Top 100 Market Cap'!O56 -> 0.3753 | D61: ='Top 100 Market Cap'!G56 -> Financials | E61: ='Top 100 Market Cap'!T56 -> https://companiesmarketcap.com/goldman-sachs/operating-margin/
A62: ='Top 100 Market Cap'!C57 -> Philip Morris International | B62: ='Top 100 Market Cap'!L57 -> 293.05 | C62: ='Top 100 Market Cap'!O57 -> 0.3414 | D62: ='Top 100 Market Cap'!G57 -> Consumer Staples | E62: ='Top 100 Market Cap'!T57 -> https://companiesmarketcap.com/philip-morris/operating-margin/
A63: ='Top 100 Market Cap'!C58 -> Novartis | B63: ='Top 100 Market Cap'!L58 -> 289.38 | C63: ='Top 100 Market Cap'!O58 -> 0.2789 | D63: ='Top 100 Market Cap'!G58 -> Technology | E63: ='Top 100 Market Cap'!T58 -> https://companiesmarketcap.com/novartis/operating-margin/
A64: ='Top 100 Market Cap'!C59 -> Alibaba | B64: ='Top 100 Market Cap'!L59 -> 283.6 | C64: ='Top 100 Market Cap'!O59 -> 0.1356 | D64: ='Top 100 Market Cap'!G59 -> Technology | E64: ='Top 100 Market Cap'!T59 -> https://companiesmarketcap.com/alibaba/operating-margin/
A65: ='Top 100 Market Cap'!C60 -> Royal Bank Of Canada | B65: ='Top 100 Market Cap'!L60 -> 282.16 | C65: ='Top 100 Market Cap'!O60 -> 0.4059 | D65: ='Top 100 Market Cap'!G60 -> Financials | E65: ='Top 100 Market Cap'!T60 -> https://companiesmarketcap.com/royal-bank-of-canada/operating-margin/
... A81: ='Top 100 Market Cap'!C76 -> L'Oréal | B81: ='Top 100 Market Cap'!L76 -> 238.07 | C81: ='Top 100 Market Cap'!O76 -> 0.193 | D81: ='Top 100 Market Cap'!G76 -> Consumer Discretionary | E81: ='Top 100 Market Cap'!T76 -> https://companiesmarketcap.com/l-oreal/operating-margin/
A82: ='Top 100 Market Cap'!C78 -> GE Vernova | B82: ='Top 100 Market Cap'!L78 -> 237.35 | C82: ='Top 100 Market Cap'!O78 -> 0.1929 | D82: ='Top 100 Market Cap'!G78 -> Energy | E82: ='Top 100 Market Cap'!T78 -> https://companiesmarketcap.com/ge-vernova/operating-margin/
A83: ='Top 100 Market Cap'!C79 -> CrowdStrike | B83: ='Top 100 Market Cap'!L79 -> 236.01 | C83: ='Top 100 Market Cap'!O79 -> 0.0003 | D83: ='Top 100 Market Cap'!G79 -> Technology | E83: ='Top 100 Market Cap'!T79 -> https://companiesmarketcap.com/crowdstrike/operating-margin/
A84: ='Top 100 Market Cap'!C80 -> Toyota | B84: ='Top 100 Market Cap'!L80 -> 232.68 | C84: ='Top 100 Market Cap'!O80 -> 0.1016 | D84: ='Top 100 Market Cap'!G80 -> Other | E84: ='Top 100 Market Cap'!T80 -> https://companiesmarketcap.com/toyota/operating-margin/
A85: ='Top 100 Market Cap'!C81 -> Amgen | B85: ='Top 100 Market Cap'!L81 -> 232.49 | C85: ='Top 100 Market Cap'!O81 -> 0.2441 | D85: ='Top 100 Market Cap'!G81 -> Technology | E85: ='Top 100 Market Cap'!T81 -> https://companiesmarketcap.com/amgen/operating-margin/
A86: ='Top 100 Market Cap'!C82 -> Thermo Fisher Scientific | B86: ='Top 100 Market Cap'!L82 -> 229.2 | C86: ='Top 100 Market Cap'!O82 -> 0.1642 | D86: ='Top 100 Market Cap'!G82 -> Technology | E86: ='Top 100 Market Cap'!T82 -> https://companiesmarketcap.com/thermo-fisher-scientific/operating-margin/
A87: ='Top 100 Market Cap'!C83 -> KLA | B87: ='Top 100 Market Cap'!L83 -> 229.12 | C87: ='Top 100 Market Cap'!O83 -> 0.4111 | D87: ='Top 100 Market Cap'!G83 -> Technology | E87: ='Top 100 Market Cap'!T83 -> https://companiesmarketcap.com/kla/operating-margin/
A88: ='Top 100 Market Cap'!C84 -> Linde | B88: ='Top 100 Market Cap'!L84 -> 225.3 | C88: ='Top 100 Market Cap'!O84 -> 0.2617 | D88: ='Top 100 Market Cap'!G84 -> Materials | E88: ='Top 100 Market Cap'!T84 -> https://companiesmarketcap.com/linde/operating-margin/
A89: ='Top 100 Market Cap'!C85 -> American Express | B89: ='Top 100 Market Cap'!L85 -> 223.55 | C89: ='Top 100 Market Cap'!O85 -> 0.192 | D89: ='Top 100 Market Cap'!G85 -> Financials | E89: ='Top 100 Market Cap'!T85 -> https://companiesmarketcap.com/american-express/operating-margin/
...
